<?xml version="1.0" ?>
<sdf version="1.7">

    <model name='quadro'>
	    <pose>0 0 0 0 0 0</pose>
	    <link name='quadro_base'>
		    <pose>0 0 0 0 -0 0</pose>
		    <inertial>
				<pose>0 0 0 0 0 0</pose>
				<mass>5</mass>
		        <inertia>
		          <ixx>0.0705</ixx>
		          <ixy>0</ixy>
		          <ixz>0</ixz>
		          <iyy>0.0689</iyy>
		          <iyz>0</iyz>
		          <izz>0.0889</izz>
		        </inertia>
			</inertial>
			<collision name='quadro_base_collision'>
				<pose >0 0 -0.02 0 -0 0</pose>
				<geometry>
				  <box>
				    <size>0.28 0.28 0.22</size>
				  </box>
				</geometry>
		    </collision>
		    <visual name='quadro_base_visual'>
				<pose >0 0 0 0 -0 0</pose>
				<geometry>
				  <mesh>
				    <scale>1 1 1</scale>
				    <uri>/home/student/Documents/rover/dae/base.dae</uri>
				  </mesh>
				</geometry>
		    </visual>
	    </link>
	    
	    <!--discribe all collisions-->
	    <link name='quadro_palka1'>
		    <pose>0.24 0 0.073 1.44 0 1.57</pose>
		    <inertial>
				<pose>0 0 0 0 0 0</pose>
				<mass>0.02</mass>
				<inertia>
					<ixx>14e-06</ixx>
					<ixy>0</ixy>
					<ixz>0</ixz>	
					<iyy>24.1e-04</iyy>
					<iyz>0</iyz>
					<izz>24.2e-04</izz>
				</inertia>
			</inertial>
			<collision name='quadro_palka1_collision'>
				<pose >0 0 0 0 0 0</pose>
				<geometry>
					<cylinder>
						<radius>0.017</radius>
						<length>0.22</length>
					</cylinder>
				</geometry>
		    </collision>
	    </link>

	    <link name='quadro_palka2'>
		    <pose>-0.003 -0.24 0.073 1.44 0 0</pose>
		    <inertial>
				<pose>0 0 0 0 0 0</pose>
				<mass>0.02</mass>
				<inertia>
					<ixx>14e-06</ixx>
					<ixy>0</ixy>
					<ixz>0</ixz>	
					<iyy>24.1e-04</iyy>
					<iyz>0</iyz>
					<izz>24.2e-04</izz>
				</inertia>
			</inertial>
			<collision name='quadro_palka2_collision'>
				<pose >0 0 0 0 0 0</pose>
				<geometry>
					<cylinder>
						<radius>0.017</radius>
						<length>0.22</length>
					</cylinder>
				</geometry>
		    </collision>
	    </link>

	    <link name='quadro_palka3'>
		    <pose>-0.24 0 0.073 -1.44 0 1.57</pose>
		    <inertial>
				<pose>0 0 0 0 0 0</pose>
				<mass>0.02</mass>
				<inertia>
					<ixx>14e-06</ixx>
					<ixy>0</ixy>
					<ixz>0</ixz>	
					<iyy>24.1e-04</iyy>
					<iyz>0</iyz>
					<izz>24.2e-04</izz>
				</inertia>
			</inertial>
			<collision name='quadro_palka3_collision'>
				<pose >0 0 0 0 0 0</pose>
				<geometry>
					<cylinder>
						<radius>0.017</radius>
						<length>0.22</length>
					</cylinder>
				</geometry>
		    </collision>
	    </link>

	    <link name='quadro_palka4'>
		    <pose>-0.003 0.24 0.073 -1.44 0 0</pose>
		    <inertial>
				<pose>0 0 0 0 0 0</pose>
				<mass>0.02</mass>
				<inertia>
					<ixx>14e-06</ixx>
					<ixy>0</ixy>
					<ixz>0</ixz>	
					<iyy>24.1e-04</iyy>
					<iyz>0</iyz>
					<izz>24.2e-04</izz>
				</inertia>
			</inertial>
			<collision name='quadro_palka4_collision'>
				<pose >0 0 0 0 0 0</pose>
				<geometry>
					<cylinder>
						<radius>0.017</radius>
						<length>0.22</length>
					</cylinder>
				</geometry>
		    </collision>
	    </link>


	    <link name='quadro_cyl1'>
		    <pose>0.346 0 0.087 0 0 0</pose>
		    <inertial>
				<pose>0 0 0 0 0 0</pose>
				<mass>0.2</mass>
				<inertia>
					<ixx>5.77e-05</ixx>
					<ixy>0</ixy>
					<ixz>0</ixz>	
					<iyy>5.77e-05</iyy>
					<iyz>0</iyz>
					<izz>6.21e-05</izz>
				</inertia>
			</inertial>
			<collision name='quadro_cyl1_collision'>
				<pose >0 0 0 0 0 0</pose>
				<geometry>
					<cylinder>
						<radius>0.025</radius>
						<length>0.04</length>
					</cylinder>
				</geometry>
		    </collision>
	    </link>

	    <link name='quadro_cyl2'>
		    <pose>-0.003 -0.349 0.087 0 0 0</pose>
		    <inertial>
				<pose>0 0 0 0 0 0</pose>
				<mass>0.327</mass>
				<inertia>
					<ixx>14e-06</ixx>
					<ixy>0</ixy>
					<ixz>0</ixz>	
					<iyy>24.1e-04</iyy>
					<iyz>0</iyz>
					<izz>24.2e-04</izz>
				</inertia>
			</inertial>
			<collision name='quadro_cyl2_collision'>
				<pose >0 0 0 0 0 0</pose>
				<geometry>
					<cylinder>
						<radius>0.025</radius>
						<length>0.04</length>
					</cylinder>
				</geometry>
		    </collision>
	    </link>

	    <link name='quadro_cyl3'>
		    <pose>-0.353 0 0.087 0 0 0</pose>
		    <inertial>
				<pose>0 0 0 0 0 0</pose>
				<mass>0.327</mass>
				<inertia>
					<ixx>14e-06</ixx>
					<ixy>0</ixy>
					<ixz>0</ixz>	
					<iyy>24.1e-04</iyy>
					<iyz>0</iyz>
					<izz>24.2e-04</izz>
				</inertia>
			</inertial>
			<collision name='quadro_cyl3_collision'>
				<pose >0 0 0 0 0 0</pose>
				<geometry>
					<cylinder>
						<radius>0.025</radius>
						<length>0.04</length>
					</cylinder>
				</geometry>
		    </collision>
	    </link>

	   	<link name='quadro_cyl4'>
		    <pose>-0.003 0.349 0.087 0 0 0</pose>
		    <inertial>
				<pose>0 0 0 0 0 0</pose>
				<mass>0.327</mass>
				<inertia>
					<ixx>14e-06</ixx>
					<ixy>0</ixy>
					<ixz>0</ixz>	
					<iyy>24.1e-04</iyy>
					<iyz>0</iyz>
					<izz>24.2e-04</izz>
				</inertia>
			</inertial>
			<collision name='quadro_cyl4_collision'>
				<pose >0 0 0 0 0 0</pose>
				<geometry>
					<cylinder>
						<radius>0.025</radius>
						<length>0.04</length>
					</cylinder>
				</geometry>
		    </collision>
	    </link>


	    <link name='quadro_chassi_l1'>
		    <pose>-0.14 0.163 -0.14 0.353 0.379 0</pose>
		    <inertial>
				<pose>0 0 0 0 0 0</pose>
				<mass>0.01</mass>
				<inertia>
					<ixx>14e-06</ixx>
					<ixy>0</ixy>
					<ixz>0</ixz>	
					<iyy>24.1e-04</iyy>
					<iyz>0</iyz>
					<izz>24.2e-04</izz>
				</inertia>
			</inertial>
			<collision name='quadro_chassi_l1_collision'>
				<pose >0 0 0 0 0 0</pose>
				<geometry>
					<cylinder>
						<radius>0.0075</radius>
						<length>0.32</length>
					</cylinder>
				</geometry>
		    </collision>
	    </link>

	    <link name='quadro_chassi_l2'>
		    <pose>0.125 0.163 -0.14 0.353 -0.33 0</pose>
		    <inertial>
				<pose>0 0 0 0 0 0</pose>
				<mass>0.01</mass>
				<inertia>
					<ixx>14e-06</ixx>
					<ixy>0</ixy>
					<ixz>0</ixz>	
					<iyy>24.1e-04</iyy>
					<iyz>0</iyz>
					<izz>24.2e-04</izz>
				</inertia>
			</inertial>
			<collision name='quadro_chassi_l2_collision'>
				<pose >0 0 0 0 0 0</pose>
				<geometry>
					<cylinder>
						<radius>0.0075</radius>
						<length>0.32</length>
					</cylinder>
				</geometry>
		    </collision>
	    </link>

	    <link name='quadro_chassi_l3'>
		    <pose>-0.007 0.219 -0.285 1.571 0 1.571</pose>
		    <inertial>
				<pose>0 0 0 0 0 0</pose>
				<mass>0.01</mass>
				<inertia>
					<ixx>2.42e-07</ixx>
					<ixy>0</ixy>
					<ixz>0</ixz>	
					<iyy>1.87e-04</iyy>
					<iyz>0</iyz>
					<izz>1.87e-04</izz>
				</inertia>
			</inertial>
			<collision name='quadro_chassi_l3_collision'>
				<pose >0 0 0 0 0 0</pose>
				<geometry>
					<cylinder>
						<radius>0.007</radius>
						<length>0.475</length>
					</cylinder>
				</geometry>
		    </collision>
	    </link>

	    <link name='quadro_chassi_r1'>
		    <pose>-0.14 -0.163 -0.14 -0.353 0.379 0</pose>
		    <inertial>
				<pose>0 0 0 0 0 0</pose>
				<mass>0.01</mass>
				<inertia>
					<ixx>14e-06</ixx>
					<ixy>0</ixy>
					<ixz>0</ixz>	
					<iyy>24.1e-04</iyy>
					<iyz>0</iyz>
					<izz>24.2e-04</izz>
				</inertia>
			</inertial>
			<collision name='quadro_chassi_r1_collision'>
				<pose >0 0 0 0 0 0</pose>
				<geometry>
					<cylinder>
						<radius>0.0075</radius>
						<length>0.32</length>
					</cylinder>
				</geometry>
		    </collision>
	    </link>

	    <link name='quadro_chassi_r2'>
		    <pose>0.125 -0.163 -0.14 -0.353 -0.33 0</pose>
		    <inertial>
				<pose>0 0 0 0 0 0</pose>
				<mass>0.01</mass>
				<inertia>
					<ixx>14e-06</ixx>
					<ixy>0</ixy>
					<ixz>0</ixz>	
					<iyy>24.1e-04</iyy>
					<iyz>0</iyz>
					<izz>24.2e-04</izz>
				</inertia>
			</inertial>
			<collision name='quadro_chassi_r2_collision'>
				<pose >0 0 0 0 0 0</pose>
				<geometry>
					<cylinder>
						<radius>0.0075</radius>
						<length>0.32</length>
					</cylinder>
				</geometry>
		    </collision>
	    </link>

	    <link name='quadro_chassi_r3'>
		    <pose>-0.007 -0.219 -0.285 1.571 0 1.571</pose>
		    <inertial>
				<pose>0 0 0 0 0 0</pose>
				<mass>0.01</mass>
				<inertia>
					<ixx>14e-06</ixx>
					<ixy>0</ixy>
					<ixz>0</ixz>	
					<iyy>24.1e-04</iyy>
					<iyz>0</iyz>
					<izz>24.2e-04</izz>
				</inertia>
			</inertial>
			<collision name='quadro_chassi_r1_collision'>
				<pose >0 0 0 0 0 0</pose>
				<geometry>
					<cylinder>
						<radius>0.007</radius>
						<length>0.475</length>
					</cylinder>
				</geometry>
		    </collision>
	    </link>

	    <!-- описываем камеру и ее joint-->
	    <link name='quadro1_mount'>
		    <pose>0.2128 0 -0.1265 0 0 0</pose>
		    <inertial>
				<pose>0 0 0 0 0 0</pose>
				<mass>0.01</mass>
				<inertia>
					<ixx>1.47e-05</ixx>
					<ixy>0</ixy>
					<ixz>0</ixz>	
					<iyy>2.41e-05</iyy>
					<iyz>0</iyz>
					<izz>1.88e-05</izz>
				</inertia>
			</inertial>
			<collision name='quadro_mount1_collision'>
				<pose >-0.0128 0 0.0845 0 0 0</pose>
				<geometry>
					<box>
						<size>0.13 0.075 0.11</size>>
					</box>
				</geometry>
		    </collision>
		    <visual name='quadro_mount1_visual'>
				<pose >0 0 0 0 -0 0</pose>
				<geometry>
				  <mesh>
				    <scale>1 1 1</scale>
				    <uri>/home/student/Documents/rover/dae/mount1.dae</uri>
				  </mesh>
				</geometry>
		    </visual>
	    </link>
	    <joint name='quadro_mount1_joint' type='revolute'>
		    <child>quadro_mount1</child>
		    <parent>quadro_base</parent>
		    <axis>
				<xyz>0 0 1</xyz>
				<limit>
					<lower>-1e+16</lower>
					<upper>1e+16</upper>
				</limit>
				<dynamics>
          			<damping>0.004</damping>
				</dynamics>
			</axis>
	    </joint>

	    <link name='quadro_mount2'>
		    <pose>0.219 0 -0.197 0 0 0</pose>
		    <inertial>
				<pose>0 0 0 0 0 0</pose>
				<mass>0.01</mass>
				<inertia>
					<ixx>14e-06</ixx>
					<ixy>0</ixy>
					<ixz>0</ixz>	
					<iyy>24.1e-04</iyy>
					<iyz>0</iyz>
					<izz>24.2e-04</izz>
				</inertia>
			</inertial>
			<collision name='quadro_mount2_collision'>
				<pose >0 0 0 0 0 0</pose>
				<geometry>
					<box>
						<size>0.01 0.01 0.01</size>>
					</box>
				</geometry>
		    </collision>
		    <visual name='quadro_mount1_visual'>
				<pose >0 0 0 0 0 0</pose>
				<geometry>
				  <mesh>
				    <scale>1 1 1</scale>
				    <uri>/home/student/Documents/rover/dae/mount2.dae</uri>
				  </mesh>
				</geometry>
		    </visual>
	    </link>
	    <joint name='quadro_mount2_joint' type='revolute'>
		    <child>quadro_mount2</child>
		    <parent>quadro_mount1</parent>
		    <axis>
				<xyz>1 0 0</xyz>
				<limit>
					<lower>-1e+16</lower>
					<upper>1e+16</upper>
				</limit>
				<dynamics>
          			<damping>0.004</damping>
				</dynamics>
			</axis>
	    </joint>

	    <link name='quadro_camera'>
		    <pose>0.266 0 -0.197 0 0 0</pose>
		    <inertial>
				<pose>0 0 0 0 0 0</pose>
				<mass>0.4</mass>
				<inertia>
					<ixx>0.00100763</ixx>
					<ixy>0</ixy>
					<ixz>0</ixz>	
					<iyy>0.00100763</iyy>
					<iyz>0</iyz>
					<izz>0.00097366</izz>
				</inertia>
			</inertial>
			<collision name='quadro_camera_collision'>
				<pose >-0.019 0 0.037 0 0 0</pose>
				<geometry>
					<cylinder>
						<radius>0.07/radius>
						<length>0.125</length>
					</cylinder>
				</geometry>
		    </collision>
	    </link>
	    <joint name='quadro_mount2_joint' type='revolute'>
		    <child>quadro_camera</child>
		    <parent>quadro_mount2</parent>
		    <axis>
				<xyz>1 0 0</xyz>
				<limit>
					<lower>-1.57</lower>
					<upper>2.53</upper>
				</limit>
				<dynamics>
          			<damping>0.004</damping>
				</dynamics>
			</axis>
	    </joint>


	    <link name='quadro_rotor1'>
		    <pose>0.346 0 0.115 0 0 0</pose>
		    <inertial>
				<pose>0 0 0 0 0 0</pose>
				<mass>0.1</mass>
				<inertia>
		          <ixx>14e-06</ixx>
		          <ixy>0</ixy>
		          <ixz>0</ixz>
		          <iyy>24.1e-04</iyy>
		          <iyz>0</iyz>
		          <izz>24.2e-04</izz>
				</inertia>
			</inertial>
			<collision name='quadro_rotor1_collision'>
				<pose >0 0 0 0 0 0</pose>
				<geometry>
					<cylinder>
						<radius>0.175</radius>
						<length>0.015</length>
					</cylinder>
				</geometry>
		    </collision>
		    <visual name='quadro_rotor1_visual'>
				<pose >0 0 0 0 -0 0</pose>
				<geometry>
				  <mesh>
				    <scale>1 1 1</scale>
				    <uri>/home/student/Documents/rover/dae/vint.dae</uri>
				  </mesh>
				</geometry>
		    </visual>
	    </link>
	    <joint name='quadro_rotor1_joint' type='revolute'>
		    <child>quadro_rotor1</child>
		    <parent>quadro_base</parent>
		    <axis>
				<xyz>0 0 1</xyz>
				<limit>
					<lower>-1e+16</lower>
					<upper>1e+16</upper>
				</limit>
				<dynamics>
          			<damping>0.004</damping>
				</dynamics>
			</axis>
	    </joint>

	    <link name='quadro_rotor2'>
		    <pose>-0.003 -0.349 0.115 0 0 0</pose>
		    <inertial>
				<pose>0 0 0 0 0 0</pose>
				<mass>0.1</mass>
				<inertia>
		          <ixx>14e-06</ixx>
		          <ixy>0</ixy>
		          <ixz>0</ixz>
		          <iyy>24.1e-04</iyy>
		          <iyz>0</iyz>
		          <izz>24.2e-04</izz>
				</inertia>
			</inertial>
			<collision name='quadro_rotor2_collision'>
				<pose >0 0 0 0 0 0</pose>
				<geometry>
					<cylinder>
						<radius>0.175</radius>
						<length>0.015</length>
					</cylinder>
				</geometry>
		    </collision>
		    <visual name='quadro_rotor2_visual'>
				<pose >0 0 0 0 -0 0</pose>
				<geometry>
				  <mesh>
				    <scale>1 1 1</scale>
				    <uri>/home/student/Documents/rover/dae/vint.dae</uri>
				  </mesh>
				</geometry>
		    </visual>
	    </link>
	    <joint name='quadro_rotor2_joint' type='revolute'>
		    <child>quadro_rotor2</child>
		    <parent>quadro_base</parent>
		    <axis>
				<xyz>0 0 1</xyz>
				<limit>
					<lower>-1e+16</lower>
					<upper>1e+16</upper>
				</limit>
				<dynamics>
          			<damping>0.004</damping>
				</dynamics>
			</axis>
	    </joint>

	    <link name='quadro_rotor3'>
		    <pose>-0.352 0 0.115 0 0 0</pose>
		    <inertial>
				<pose>0 0 0 0 0 0</pose>
				<mass>0.1</mass>
				<inertia>
		          <ixx>14e-06</ixx>
		          <ixy>0</ixy>
		          <ixz>0</ixz>
		          <iyy>24.1e-04</iyy>
		          <iyz>0</iyz>
		          <izz>24.2e-04</izz>
				</inertia>
			</inertial>
			<collision name='quadro_rotor3_collision'>
				<pose >0 0 0 0 0 0</pose>
				<geometry>
					<cylinder>
						<radius>0.175</radius>
						<length>0.015</length>
					</cylinder>
				</geometry>
		    </collision>
		    <visual name='quadro_rotor3_visual'>
				<pose >0 0 0 0 -0 0</pose>
				<geometry>
				  <mesh>
				    <scale>1 1 1</scale>
				    <uri>/home/student/Documents/rover/dae/vint.dae</uri>
				  </mesh>
				</geometry>
		    </visual>
	    </link>
	    <joint name='quadro_rotor3_joint' type='revolute'>
		    <child>quadro_rotor3</child>
		    <parent>quadro_base</parent>
		    <axis>
				<xyz>0 0 1</xyz>
				<limit>
					<lower>-1e+16</lower>
					<upper>1e+16</upper>
				</limit>
				<dynamics>
          			<damping>0.004</damping>
				</dynamics>
			</axis>
	    </joint>

	    <link name='quadro_rotor4'>
		    <pose>-0.003 0.349 0.115 0 0 0</pose>
		    <inertial>
				<pose>0 0 0 0 0 0</pose>
				<mass>0.1</mass>
				<inertia>
		          <ixx>14e-06</ixx>
		          <ixy>0</ixy>
		          <ixz>0</ixz>
		          <iyy>24.1e-04</iyy>
		          <iyz>0</iyz>
		          <izz>24.2e-04</izz>
				</inertia>
			</inertial>
			<collision name='quadro_rotor4_collision'>
				<pose >0 0 0 0 0 0</pose>
				<geometry>
					<cylinder>
						<radius>0.175</radius>
						<length>0.015</length>
					</cylinder>
				</geometry>
		    </collision>
		    <visual name='quadro_rotor4_visual'>
				<pose >0 0 0 0 -0 0</pose>
				<geometry>
				  <mesh>
				    <scale>1 1 1</scale>
				    <uri>/home/student/Documents/rover/dae/vint.dae</uri>
				  </mesh>
				</geometry>
		    </visual>
	    </link>
	    <joint name='quadro_rotor4_joint' type='revolute'>
		    <child>quadro_rotor4</child>
		    <parent>quadro_base</parent>
		    <axis>
				<xyz>0 0 1</xyz>
				<limit>
					<lower>-1e+16</lower>
					<upper>1e+16</upper>
				</limit>
				<dynamics>
          			<damping>0.004</damping>
				</dynamics>
			</axis>
	    </joint>
	    
    </model>
       
</sdf>
